<?xml version="1.0"?>
<robot name="caster_wheel" xmlns:xacro="http://ros.org/wiki/xacro">
    <xacro:include filename="$(find gobot_description)/urdf/wheels/caster.gazebo.xacro" />

    <!-- Caster Wheels -->
    <xacro:property name="caster_wheel_radius" value="0.037" /> 
    <xacro:property name="caster_wheel_height" value="0.023" />
    <xacro:property name="caster_wheel_mass" value="0.2" />

    <xacro:macro name="cylinder_inertia" params="m r h">
        <inertia  ixx="${m*(3*r*r+h*h)/12}" ixy = "0" ixz = "0"
        iyy="${m*(3*r*r+h*h)/12}" iyz = "0"
        izz="${m*r*r/2}" /> 
    </xacro:macro>

    <xacro:macro name="caster_wheel" params="fb lr parent translateX translateY translateZ flipY"> <!--fb : front, back ; lr: left, right -->
        <link name="${fb}_${lr}_caster_wheel">
            <visual>
                <origin xyz="0 0 0" rpy="${flipY*pi/2} 0  0 " /> 
                <geometry>
                    <cylinder length="${caster_wheel_height}" radius="${caster_wheel_radius}" />
                </geometry>
            </visual>
            <collision>
                <origin xyz="0 0 0" rpy="${flipY*pi/2} 0 0 " />
                <geometry>
                    <cylinder length="${caster_wheel_height}" radius="${caster_wheel_radius}" />
                </geometry>
            </collision>
            <inertial>
                <mass value="${caster_wheel_mass}" />
                <origin xyz="0 0 0" />
                <cylinder_inertia  m="${caster_wheel_mass}" r="${caster_wheel_radius}" h="${caster_wheel_height}" />
            </inertial>
        </link>

        <joint name="${fb}_${lr}_caster_wheel_joint" type="continuous">
            <parent link="${parent}"/>
            <child link="${fb}_${lr}_caster_wheel"/>
            <origin xyz="${translateX} ${translateY} ${translateZ}" rpy="0 0 0"/> 
            <axis xyz="0 1 0" rpy="0 0 0"/>
        </joint>

        <!-- gazebo extensions -->
        <xacro:caster_wheel_gazebo name="${fb}_${lr}_caster_wheel" />
    </xacro:macro>
</robot>
