<?xml version="1.0"?>
<robot name="wheel" xmlns:xacro="http://ros.org/wiki/xacro">
    <xacro:include filename="$(find gobot_description)/urdf/wheels/wheel.gazebo.xacro" />

    <xacro:macro name="cylinder_inertia" params="m r h">
        <inertia  ixx="${m*(3*r*r+h*h)/12}" ixy = "0" ixz = "0"
            iyy="${m*(3*r*r+h*h)/12}" iyz = "0"
            izz="${m*r*r/2}" /> 
    </xacro:macro>

    <xacro:macro name="wheel" params="fb lr parent translateX translateY translateZ flipY radius length mass"> <!--fb : front, back ; lr: left, right -->
        <link name="${fb}_${lr}_wheel">
            <visual>
                <origin xyz="0 0 0" rpy="${flipY*pi/2} 0  0 " /> 
                <geometry>
                    <cylinder length="${length}" radius="${radius}" />
                </geometry>
                <material name="DarkGray" />
            </visual>
            <collision>
                <origin xyz="0 0 0" rpy="${flipY*pi/2} 0 0 " />
                <geometry>
                    <cylinder length="${length}" radius="${radius}" />
                </geometry>
            </collision>
            <inertial>
                <mass value="${mass}" />
                <origin xyz="0 0 0" />
                <cylinder_inertia  m="${mass}" r="${radius}" h="${length}" />
            </inertial>
        </link>


        <joint name="${fb}_${lr}_wheel_joint" type="continuous">
            <parent link="${parent}"/>
            <child link="${fb}_${lr}_wheel"/>
            <origin xyz="${translateX} ${translateY} ${translateZ}" rpy="0 0 0" /> 
            <axis xyz="0 1 0" rpy="0 0 0" />
            <limit effort="100" velocity="100"/>
            <joint_properties damping="0.0" friction="0.0"/>
        </joint>
        
        <!-- gazebo extensions -->
        <xacro:wheel_gazebo fb="${fb}" lr="${lr}"/>

    </xacro:macro>
</robot>
