<?xml version="1.0"?>
<robot name="bumper" xmlns:xacro="http://ros.org/wiki/xacro">
    <xacro:include filename="$(find gobot_description)/urdf/bumper/bumper.gazebo.xacro" />

    <xacro:macro name="bumper" params="name parent width length height translateX translateY translateZ collision jointLowerLimit jointUpperLimit jointVelocity">
        <link name="${name}">
            <collision name="${name}">
                <origin xyz="0 0 0" rpy="0 0 0"/>
                <geometry>
                    <box size="${width} ${length} ${height}"/>
                </geometry> 
            </collision>
            <visual>
                <origin xyz="0 0 0" rpy="0 0 0"/>
                <geometry>
                    <box size="${width} ${length} ${height}"/>
                </geometry>
            </visual>
            <inertial>
                <origin xyz="0 0 0" rpy="0 0 0"/>
                <mass value="0.4"/>
                <box_inertia m="0.4" x="${width}" y="${length}" z="${height}"/>
            </inertial>
        </link>

        <!-- The joint between the bumper and parent -->
        <joint name="${name}_joint" type="prismatic">
            <parent link="${parent}"/>
            <child link="${name}"/>
            <origin xyz="${translateX} ${translateY} ${translateZ}" rpy="0 0 0"/>
            <axis xyz="01 0 0"/>
            <limit effort="1" lower="${jointLowerLimit}" upper="${jointUpperLimit}" velocity="${jointVelocity}"/>
        </joint>

        <!-- gazebo extensions -->
        <xacro:bumper_gazebo name="${name}" collision="${collision}"/>
    </xacro:macro>
</robot>
