<?xml version="1.0" ?>
<!-- =================================================================================== -->
<!-- |    This document was autogenerated by xacro from gobot.urdf.xacro               | -->
<!-- |    EDITING THIS FILE BY HAND IS NOT RECOMMENDED                                 | -->
<!-- =================================================================================== -->
<robot name="gobot" xmlns:xacro="http://ros.org/wiki/xacro">
  <material name="black">
    <color rgba="0.0 0.0 0.0 1.0"/>
  </material>
  <material name="blue">
    <color rgba="0.0 0.0 0.8 1.0"/>
  </material>
  <material name="green">
    <color rgba="0.0 0.8 0.0 1.0"/>
  </material>
  <material name="grey">
    <color rgba="0.2 0.2 0.2 1.0"/>
  </material>
  <material name="orange">
    <color rgba="1.0 0.423529411765 0.0392156862745 1.0"/>
  </material>
  <material name="brown">
    <color rgba="0.870588235294 0.811764705882 0.764705882353 1.0"/>
  </material>
  <material name="red">
    <color rgba="0.8 0.0 0.0 1.0"/>
  </material>
  <material name="white">
    <color rgba="1.0 1.0 1.0 1.0"/>
  </material>
  <!-- in kg-->
  <!--fb : front, back ; lr: left, right -->
  <!-- The lower part of the base link -->
  <link name="base_link">
    <collision>
      <origin rpy="0 0 0" xyz="0 0 0.05"/>
      <geometry>
        <box size="0.50 0.49 0.068"/>
      </geometry>
    </collision>
    <visual>
      <origin rpy="0 0 0" xyz="0 0 0.05"/>
      <geometry>
        <box size="0.50 0.49 0.068"/>
      </geometry>
    </visual>
    <inertial>
      <origin rpy="0 0 0" xyz="0 0 0.05"/>
      <mass value="4"/>
      <inertia ixx="0.121141666667" ixy="0" ixz="0" iyy="0.141509333333" iyz="0" izz="0.141509333333"/>
    </inertial>
  </link>
  <gazebo reference="base_link">
    <material>Gazebo/Grey</material>
  </gazebo>
  <!-- The middle part of the base link -->
  <link name="mid_base_link">
    <collision>
      <origin rpy="0 0 0" xyz="0 0 0.05"/>
      <geometry>
        <box size="0.448 0.599 0.022"/>
      </geometry>
    </collision>
    <visual>
      <origin rpy="0 0 0" xyz="0 0 0.05"/>
      <geometry>
        <box size="0.448 0.599 0.022"/>
      </geometry>
    </visual>
    <inertial>
      <origin rpy="0 0 0" xyz="0 0 0.05"/>
      <mass value="2"/>
      <inertia ixx="0.0598808333333" ixy="0" ixz="0" iyy="0.0335313333333" iyz="0" izz="0.0335313333333"/>
    </inertial>
  </link>
  <gazebo reference="mid_base_link">
    <material>Gazebo/Grey</material>
  </gazebo>
  <!-- The top part of the base link -->
  <link name="top_base_link">
    <collision>
      <origin rpy="0 0 0" xyz="0 0 0.05"/>
      <geometry>
        <box size="0.50 0.49 0.095"/>
      </geometry>
    </collision>
    <visual>
      <origin rpy="0 0 0" xyz="0 0 0.05"/>
      <geometry>
        <box size="0.50 0.49 0.095"/>
      </geometry>
    </visual>
    <inertial>
      <origin rpy="0 0 0" xyz="0 0 0.05"/>
      <mass value="4"/>
      <inertia ixx="0.122608666667" ixy="0" ixz="0" iyy="0.142976333333" iyz="0" izz="0.142976333333"/>
    </inertial>
  </link>
  <gazebo reference="top_base_link">
    <material>Gazebo/Grey</material>
  </gazebo>
  <!-- The joint between the lower and middle part of the base link -->
  <joint name="lower_mid_joint" type="fixed">
    <origin xyz="-0.1 0 0.045"/>
    <parent link="base_link"/>
    <child link="mid_base_link"/>
  </joint>
  <!-- The joint between the middle and top part of the base link -->
  <joint name="mid_top_joint" type="fixed">
    <origin xyz="0.1 0 0.0585"/>
    <parent link="mid_base_link"/>
    <child link="top_base_link"/>
  </joint>
  <link name="front_right_cyl_bumper">
    <visual>
      <origin rpy="0 0  0 " xyz="0 0 0"/>
      <geometry>
        <cylinder length="0.041" radius="0.05"/>
      </geometry>
    </visual>
    <collision>
      <origin rpy="0 0 0 " xyz="0 0 0"/>
      <geometry>
        <cylinder length="0.041" radius="0.05"/>
      </geometry>
    </collision>
    <inertial>
      <mass value="0.1"/>
      <origin xyz="0 0 0"/>
      <inertia ixx="7.65083333333e-05" ixy="0" ixz="0" iyy="7.65083333333e-05" iyz="0" izz="0.000125"/>
    </inertial>
  </link>
  <joint name="front_right_cyl_bumper_joint" type="prismatic">
    <parent link="base_link"/>
    <child link="front_right_cyl_bumper"/>
    <origin rpy="0 0 0" xyz="0.2895 -0.2645 0.05"/>
    <axis xyz="1 0 0"/>
    <limit effort="1000" lower="-0.005" upper="0" velocity="0.5"/>
  </joint>
  <gazebo reference="front_right_cyl_bumper">
    <material>Gazebo/Black</material>
    <sensor name="front_right_cyl_bumper_sensor" type="contact">
      <contact>
        <collision>base_link_fixed_joint_lump__front_right_cyl_bumper_collision_12</collision>
      </contact>
      <plugin filename="libgazebo_ros_bumper.so" name="front_right_cyl_bumper_gazebo_ros_bumper_controller">
        <alwaysOn>true</alwaysOn>
        <updateRate>20</updateRate>
        <bumperTopicName>front_right_cyl_bumper</bumperTopicName>
        <frameName>world</frameName>
      </plugin>
    </sensor>
  </gazebo>
  <link name="front_left_cyl_bumper">
    <visual>
      <origin rpy="0 0  0 " xyz="0 0 0"/>
      <geometry>
        <cylinder length="0.041" radius="0.05"/>
      </geometry>
    </visual>
    <collision>
      <origin rpy="0 0 0 " xyz="0 0 0"/>
      <geometry>
        <cylinder length="0.041" radius="0.05"/>
      </geometry>
    </collision>
    <inertial>
      <mass value="0.1"/>
      <origin xyz="0 0 0"/>
      <inertia ixx="7.65083333333e-05" ixy="0" ixz="0" iyy="7.65083333333e-05" iyz="0" izz="0.000125"/>
    </inertial>
  </link>
  <joint name="front_left_cyl_bumper_joint" type="prismatic">
    <parent link="base_link"/>
    <child link="front_left_cyl_bumper"/>
    <origin rpy="0 0 0" xyz="0.2895 0.2645 0.05"/>
    <axis xyz="1 0 0"/>
    <limit effort="1000" lower="-0.005" upper="0" velocity="0.5"/>
  </joint>
  <gazebo reference="front_left_cyl_bumper">
    <material>Gazebo/Black</material>
    <sensor name="front_left_cyl_bumper_sensor" type="contact">
      <contact>
        <collision>base_link_fixed_joint_lump__front_left_cyl_bumper_collision_10</collision>
      </contact>
      <plugin filename="libgazebo_ros_bumper.so" name="front_left_cyl_bumper_gazebo_ros_bumper_controller">
        <alwaysOn>true</alwaysOn>
        <updateRate>20</updateRate>
        <bumperTopicName>front_left_cyl_bumper</bumperTopicName>
        <frameName>world</frameName>
      </plugin>
    </sensor>
  </gazebo>
  <link name="back_right_cyl_bumper">
    <visual>
      <origin rpy="0 0  0 " xyz="0 0 0"/>
      <geometry>
        <cylinder length="0.041" radius="0.05"/>
      </geometry>
    </visual>
    <collision>
      <origin rpy="0 0 0 " xyz="0 0 0"/>
      <geometry>
        <cylinder length="0.041" radius="0.05"/>
      </geometry>
    </collision>
    <inertial>
      <mass value="0.1"/>
      <origin xyz="0 0 0"/>
      <inertia ixx="7.65083333333e-05" ixy="0" ixz="0" iyy="7.65083333333e-05" iyz="0" izz="0.000125"/>
    </inertial>
  </link>
  <joint name="back_right_cyl_bumper_joint" type="prismatic">
    <parent link="base_link"/>
    <child link="back_right_cyl_bumper"/>
    <origin rpy="0 0 0" xyz="-0.2895 -0.2645 0.05"/>
    <axis xyz="1 0 0"/>
    <limit effort="1000" lower="0" upper="0.005" velocity="-0.5"/>
  </joint>
  <gazebo reference="back_right_cyl_bumper">
    <material>Gazebo/Black</material>
    <sensor name="back_right_cyl_bumper_sensor" type="contact">
      <contact>
        <collision>base_link_fixed_joint_lump__back_right_cyl_bumper_collision_4</collision>
      </contact>
      <plugin filename="libgazebo_ros_bumper.so" name="back_right_cyl_bumper_gazebo_ros_bumper_controller">
        <alwaysOn>true</alwaysOn>
        <updateRate>20</updateRate>
        <bumperTopicName>back_right_cyl_bumper</bumperTopicName>
        <frameName>world</frameName>
      </plugin>
    </sensor>
  </gazebo>
  <link name="back_left_cyl_bumper">
    <visual>
      <origin rpy="0 0  0 " xyz="0 0 0"/>
      <geometry>
        <cylinder length="0.041" radius="0.05"/>
      </geometry>
    </visual>
    <collision>
      <origin rpy="0 0 0 " xyz="0 0 0"/>
      <geometry>
        <cylinder length="0.041" radius="0.05"/>
      </geometry>
    </collision>
    <inertial>
      <mass value="0.1"/>
      <origin xyz="0 0 0"/>
      <inertia ixx="7.65083333333e-05" ixy="0" ixz="0" iyy="7.65083333333e-05" iyz="0" izz="0.000125"/>
    </inertial>
  </link>
  <joint name="back_left_cyl_bumper_joint" type="prismatic">
    <parent link="base_link"/>
    <child link="back_left_cyl_bumper"/>
    <origin rpy="0 0 0" xyz="-0.2895 0.2645 0.05"/>
    <axis xyz="1 0 0"/>
    <limit effort="1000" lower="0" upper="0.005" velocity="-0.5"/>
  </joint>
  <gazebo reference="back_left_cyl_bumper">
    <material>Gazebo/Black</material>
    <sensor name="back_left_cyl_bumper_sensor" type="contact">
      <contact>
        <collision>base_link_fixed_joint_lump__back_left_cyl_bumper_collision_2</collision>
      </contact>
      <plugin filename="libgazebo_ros_bumper.so" name="back_left_cyl_bumper_gazebo_ros_bumper_controller">
        <alwaysOn>true</alwaysOn>
        <updateRate>20</updateRate>
        <bumperTopicName>back_left_cyl_bumper</bumperTopicName>
        <frameName>world</frameName>
      </plugin>
    </sensor>
  </gazebo>
  <link name="front_right_bumper">
    <collision name="front_right_bumper">
      <origin rpy="0 0 0" xyz="0 0 0"/>
      <geometry>
        <box size="0.016 0.24 0.041"/>
      </geometry>
    </collision>
    <visual>
      <origin rpy="0 0 0" xyz="0 0 0"/>
      <geometry>
        <box size="0.016 0.24 0.041"/>
      </geometry>
    </visual>
    <inertial>
      <origin rpy="0 0 0" xyz="0 0 0"/>
      <mass value="0.4"/>
      <inertia ixx="0.00197603333333" ixy="0" ixz="0" iyy="6.45666666667e-05" iyz="0" izz="6.45666666667e-05"/>
    </inertial>
  </link>
  <!-- The joint between the bumper and parent -->
  <joint name="front_right_bumper_joint" type="prismatic">
    <parent link="base_link"/>
    <child link="front_right_bumper"/>
    <origin rpy="0 0 0" xyz="0.332 -0.12 0.05"/>
    <axis xyz="1 0 0"/>
    <limit effort="1000" lower="-0.005" upper="0" velocity="0.5"/>
  </joint>
  <gazebo reference="front_right_bumper">
    <material>Gazebo/Black</material>
    <sensor name="front_right_bumper_sensor" type="contact">
      <contact>
        <collision>base_link_fixed_joint_lump__front_right_bumper_collision_11</collision>
      </contact>
      <plugin filename="libgazebo_ros_bumper.so" name="front_right_bumper_gazebo_ros_bumper_controller">
        <alwaysOn>true</alwaysOn>
        <updateRate>20</updateRate>
        <bumperTopicName>front_right_bumper</bumperTopicName>
        <frameName>world</frameName>
      </plugin>
    </sensor>
  </gazebo>
  <link name="front_left_bumper">
    <collision name="front_left_bumper">
      <origin rpy="0 0 0" xyz="0 0 0"/>
      <geometry>
        <box size="0.016 0.24 0.041"/>
      </geometry>
    </collision>
    <visual>
      <origin rpy="0 0 0" xyz="0 0 0"/>
      <geometry>
        <box size="0.016 0.24 0.041"/>
      </geometry>
    </visual>
    <inertial>
      <origin rpy="0 0 0" xyz="0 0 0"/>
      <mass value="0.4"/>
      <inertia ixx="0.00197603333333" ixy="0" ixz="0" iyy="6.45666666667e-05" iyz="0" izz="6.45666666667e-05"/>
    </inertial>
  </link>
  <!-- The joint between the bumper and parent -->
  <joint name="front_left_bumper_joint" type="prismatic">
    <parent link="base_link"/>
    <child link="front_left_bumper"/>
    <origin rpy="0 0 0" xyz="0.332 0.12 0.05"/>
    <axis xyz="1 0 0"/>
    <limit effort="1000" lower="-0.005" upper="0" velocity="0.5"/>
  </joint>
  <gazebo reference="front_left_bumper">
    <material>Gazebo/Black</material>
    <sensor name="front_left_bumper_sensor" type="contact">
      <contact>
        <collision>base_link_fixed_joint_lump__front_left_bumper_collision_9</collision>
      </contact>
      <plugin filename="libgazebo_ros_bumper.so" name="front_left_bumper_gazebo_ros_bumper_controller">
        <alwaysOn>true</alwaysOn>
        <updateRate>20</updateRate>
        <bumperTopicName>front_left_bumper</bumperTopicName>
        <frameName>world</frameName>
      </plugin>
    </sensor>
  </gazebo>
  <link name="back_right_bumper">
    <collision name="back_right_bumper">
      <origin rpy="0 0 0" xyz="0 0 0"/>
      <geometry>
        <box size="0.016 0.24 0.041"/>
      </geometry>
    </collision>
    <visual>
      <origin rpy="0 0 0" xyz="0 0 0"/>
      <geometry>
        <box size="0.016 0.24 0.041"/>
      </geometry>
    </visual>
    <inertial>
      <origin rpy="0 0 0" xyz="0 0 0"/>
      <mass value="0.4"/>
      <inertia ixx="0.00197603333333" ixy="0" ixz="0" iyy="6.45666666667e-05" iyz="0" izz="6.45666666667e-05"/>
    </inertial>
  </link>
  <!-- The joint between the bumper and parent -->
  <joint name="back_right_bumper_joint" type="prismatic">
    <parent link="base_link"/>
    <child link="back_right_bumper"/>
    <origin rpy="0 0 0" xyz="-0.332 -0.12 0.05"/>
    <axis xyz="1 0 0"/>
    <limit effort="1000" lower="0" upper="0.005" velocity="-0.5"/>
  </joint>
  <gazebo reference="back_right_bumper">
    <material>Gazebo/Black</material>
    <sensor name="back_right_bumper_sensor" type="contact">
      <contact>
        <collision>base_link_fixed_joint_lump__back_right_bumper_collision_3</collision>
      </contact>
      <plugin filename="libgazebo_ros_bumper.so" name="back_right_bumper_gazebo_ros_bumper_controller">
        <alwaysOn>true</alwaysOn>
        <updateRate>20</updateRate>
        <bumperTopicName>back_right_bumper</bumperTopicName>
        <frameName>world</frameName>
      </plugin>
    </sensor>
  </gazebo>
  <link name="back_left_bumper">
    <collision name="back_left_bumper">
      <origin rpy="0 0 0" xyz="0 0 0"/>
      <geometry>
        <box size="0.016 0.24 0.041"/>
      </geometry>
    </collision>
    <visual>
      <origin rpy="0 0 0" xyz="0 0 0"/>
      <geometry>
        <box size="0.016 0.24 0.041"/>
      </geometry>
    </visual>
    <inertial>
      <origin rpy="0 0 0" xyz="0 0 0"/>
      <mass value="0.4"/>
      <inertia ixx="0.00197603333333" ixy="0" ixz="0" iyy="6.45666666667e-05" iyz="0" izz="6.45666666667e-05"/>
    </inertial>
  </link>
  <!-- The joint between the bumper and parent -->
  <joint name="back_left_bumper_joint" type="prismatic">
    <parent link="base_link"/>
    <child link="back_left_bumper"/>
    <origin rpy="0 0 0" xyz="-0.332 0.12 0.05"/>
    <axis xyz="1 0 0"/>
    <limit effort="1000" lower="0" upper="0.005" velocity="-0.5"/>
  </joint>
  <gazebo reference="back_left_bumper">
    <material>Gazebo/Black</material>
    <sensor name="back_left_bumper_sensor" type="contact">
      <contact>
        <collision>base_link_fixed_joint_lump__back_left_bumper_collision_1</collision>
      </contact>
      <plugin filename="libgazebo_ros_bumper.so" name="back_left_bumper_gazebo_ros_bumper_controller">
        <alwaysOn>true</alwaysOn>
        <updateRate>20</updateRate>
        <bumperTopicName>back_left_bumper</bumperTopicName>
        <frameName>world</frameName>
      </plugin>
    </sensor>
  </gazebo>
  <!--fb : front, back ; lr: left, right -->
  <link name="front_right_wheel">
    <visual>
      <origin rpy="1.57079632679 0  0 " xyz="0 0 0"/>
      <geometry>
        <cylinder length="0.042" radius="0.0725"/>
      </geometry>
      <material name="DarkGray"/>
    </visual>
    <collision>
      <origin rpy="1.57079632679 0 0 " xyz="0 0 0"/>
      <geometry>
        <cylinder length="0.042" radius="0.0725"/>
      </geometry>
    </collision>
    <inertial>
      <mass value="0.6"/>
      <origin xyz="0 0 0"/>
      <inertia ixx="0.0008766375" ixy="0" ixz="0" iyy="0.0008766375" iyz="0" izz="0.001576875"/>
    </inertial>
  </link>
  <joint name="front_right_wheel_joint" type="continuous">
    <parent link="base_link"/>
    <child link="front_right_wheel"/>
    <origin rpy="0 0 0" xyz="-0.057 -0.22 0.0385"/>
    <axis rpy="0 0 0" xyz="0 1 0"/>
    <limit effort="100" velocity="100"/>
    <joint_properties damping="0.0" friction="0.0"/>
  </joint>
  <gazebo reference="front_right_wheel">
    <mu1 value="1.0"/>
    <mu2 value="1.0"/>
    <kp value="10000000.0"/>
    <kd value="1.0"/>
    <fdir1 value="1 0 0"/>
    <material>Gazebo/Grey</material>
  </gazebo>
  <!-- Transmission is important to link the joints and the controller -->
  <transmission name="front_right_wheel_joint_trans">
    <type>transmission_interface/SimpleTransmission</type>
    <joint name="front_right_wheel_joint">
      <hardwareInterface>EffortJointInterface</hardwareInterface>
    </joint>
    <actuator name="front_right_wheel_joint_motor">
      <mechanicalReduction>1</mechanicalReduction>
    </actuator>
  </transmission>
  <!--fb : front, back ; lr: left, right -->
  <link name="front_left_wheel">
    <visual>
      <origin rpy="1.57079632679 0  0 " xyz="0 0 0"/>
      <geometry>
        <cylinder length="0.042" radius="0.0725"/>
      </geometry>
      <material name="DarkGray"/>
    </visual>
    <collision>
      <origin rpy="1.57079632679 0 0 " xyz="0 0 0"/>
      <geometry>
        <cylinder length="0.042" radius="0.0725"/>
      </geometry>
    </collision>
    <inertial>
      <mass value="0.6"/>
      <origin xyz="0 0 0"/>
      <inertia ixx="0.0008766375" ixy="0" ixz="0" iyy="0.0008766375" iyz="0" izz="0.001576875"/>
    </inertial>
  </link>
  <joint name="front_left_wheel_joint" type="continuous">
    <parent link="base_link"/>
    <child link="front_left_wheel"/>
    <origin rpy="0 0 0" xyz="-0.057 0.22 0.0385"/>
    <axis rpy="0 0 0" xyz="0 1 0"/>
    <limit effort="100" velocity="100"/>
    <joint_properties damping="0.0" friction="0.0"/>
  </joint>
  <gazebo reference="front_left_wheel">
    <mu1 value="1.0"/>
    <mu2 value="1.0"/>
    <kp value="10000000.0"/>
    <kd value="1.0"/>
    <fdir1 value="1 0 0"/>
    <material>Gazebo/Grey</material>
  </gazebo>
  <!-- Transmission is important to link the joints and the controller -->
  <transmission name="front_left_wheel_joint_trans">
    <type>transmission_interface/SimpleTransmission</type>
    <joint name="front_left_wheel_joint">
      <hardwareInterface>EffortJointInterface</hardwareInterface>
    </joint>
    <actuator name="front_left_wheel_joint_motor">
      <mechanicalReduction>1</mechanicalReduction>
    </actuator>
  </transmission>
  <gazebo>
    <plugin filename="libgobot_diff_drive_plugin.so" name="differential_drive_controller">
      <alwaysOn>true</alwaysOn>
      <legacyMode>false</legacyMode>
      <updateRate>40</updateRate>
      <leftJoint>front_left_wheel_joint</leftJoint>
      <rightJoint>front_right_wheel_joint</rightJoint>
      <wheelSeparation>0.44</wheelSeparation>
      <wheelDiameter>0.145</wheelDiameter>
      <commandTopic>cmd_vel</commandTopic>
      <odometryTopic>odom</odometryTopic>
      <odometryFrame>odom</odometryFrame>
      <robotBaseFrame>base_link</robotBaseFrame>
      <rosDebugLevel>na</rosDebugLevel>
      <publishWheelTF>false</publishWheelTF>
      <publishWheelJointState>false</publishWheelJointState>
      <wheelAcceleration>0</wheelAcceleration>
      <wheelTorque>5</wheelTorque>
      <odometrySource>world</odometrySource>
      <publishTf>1</publishTf>
    </plugin>
  </gazebo>
  <!--fb : front, back ; lr: left, right -->
  <link name="front_right_caster_wheel">
    <visual>
      <origin rpy="1.57079632679 0  0 " xyz="0 0 0"/>
      <geometry>
        <cylinder length="0.023" radius="0.037"/>
      </geometry>
    </visual>
    <collision>
      <origin rpy="1.57079632679 0 0 " xyz="0 0 0"/>
      <geometry>
        <cylinder length="0.023" radius="0.037"/>
      </geometry>
    </collision>
    <inertial>
      <mass value="0.2"/>
      <origin xyz="0 0 0"/>
      <inertia ixx="7.72666666667e-05" ixy="0" ixz="0" iyy="7.72666666667e-05" iyz="0" izz="0.0001369"/>
    </inertial>
  </link>
  <joint name="front_right_caster_wheel_joint" type="continuous">
    <parent link="base_link"/>
    <child link="front_right_caster_wheel"/>
    <origin rpy="0 0 0" xyz="0.184 -0.2095 0.003"/>
    <axis rpy="0 0 0" xyz="0 1 0"/>
  </joint>
  <gazebo reference="front_right_caster_wheel">
    <material>Gazebo/Black</material>
    <mu1 value="0"/>
    <mu2 value="0"/>
    <kp value="10000000.0"/>
    <kd value="1.0"/>
    <fdir1 value="1 0 0"/>
  </gazebo>
  <!--fb : front, back ; lr: left, right -->
  <link name="front_left_caster_wheel">
    <visual>
      <origin rpy="1.57079632679 0  0 " xyz="0 0 0"/>
      <geometry>
        <cylinder length="0.023" radius="0.037"/>
      </geometry>
    </visual>
    <collision>
      <origin rpy="1.57079632679 0 0 " xyz="0 0 0"/>
      <geometry>
        <cylinder length="0.023" radius="0.037"/>
      </geometry>
    </collision>
    <inertial>
      <mass value="0.2"/>
      <origin xyz="0 0 0"/>
      <inertia ixx="7.72666666667e-05" ixy="0" ixz="0" iyy="7.72666666667e-05" iyz="0" izz="0.0001369"/>
    </inertial>
  </link>
  <joint name="front_left_caster_wheel_joint" type="continuous">
    <parent link="base_link"/>
    <child link="front_left_caster_wheel"/>
    <origin rpy="0 0 0" xyz="0.184 0.2095 0.003"/>
    <axis rpy="0 0 0" xyz="0 1 0"/>
  </joint>
  <gazebo reference="front_left_caster_wheel">
    <material>Gazebo/Black</material>
    <mu1 value="0"/>
    <mu2 value="0"/>
    <kp value="10000000.0"/>
    <kd value="1.0"/>
    <fdir1 value="1 0 0"/>
  </gazebo>
  <!--fb : front, back ; lr: left, right -->
  <link name="back_right_caster_wheel">
    <visual>
      <origin rpy="1.57079632679 0  0 " xyz="0 0 0"/>
      <geometry>
        <cylinder length="0.023" radius="0.037"/>
      </geometry>
    </visual>
    <collision>
      <origin rpy="1.57079632679 0 0 " xyz="0 0 0"/>
      <geometry>
        <cylinder length="0.023" radius="0.037"/>
      </geometry>
    </collision>
    <inertial>
      <mass value="0.2"/>
      <origin xyz="0 0 0"/>
      <inertia ixx="7.72666666667e-05" ixy="0" ixz="0" iyy="7.72666666667e-05" iyz="0" izz="0.0001369"/>
    </inertial>
  </link>
  <joint name="back_right_caster_wheel_joint" type="continuous">
    <parent link="base_link"/>
    <child link="back_right_caster_wheel"/>
    <origin rpy="0 0 0" xyz="-0.244 -0.1895 0.011"/>
    <axis rpy="0 0 0" xyz="0 1 0"/>
  </joint>
  <gazebo reference="back_right_caster_wheel">
    <material>Gazebo/Black</material>
    <mu1 value="0"/>
    <mu2 value="0"/>
    <kp value="10000000.0"/>
    <kd value="1.0"/>
    <fdir1 value="1 0 0"/>
  </gazebo>
  <!--fb : front, back ; lr: left, right -->
  <link name="back_left_caster_wheel">
    <visual>
      <origin rpy="1.57079632679 0  0 " xyz="0 0 0"/>
      <geometry>
        <cylinder length="0.023" radius="0.037"/>
      </geometry>
    </visual>
    <collision>
      <origin rpy="1.57079632679 0 0 " xyz="0 0 0"/>
      <geometry>
        <cylinder length="0.023" radius="0.037"/>
      </geometry>
    </collision>
    <inertial>
      <mass value="0.2"/>
      <origin xyz="0 0 0"/>
      <inertia ixx="7.72666666667e-05" ixy="0" ixz="0" iyy="7.72666666667e-05" iyz="0" izz="0.0001369"/>
    </inertial>
  </link>
  <joint name="back_left_caster_wheel_joint" type="continuous">
    <parent link="base_link"/>
    <child link="back_left_caster_wheel"/>
    <origin rpy="0 0 0" xyz="-0.244 0.1895 0.011"/>
    <axis rpy="0 0 0" xyz="0 1 0"/>
  </joint>
  <gazebo reference="back_left_caster_wheel">
    <material>Gazebo/Black</material>
    <mu1 value="0"/>
    <mu2 value="0"/>
    <kp value="10000000.0"/>
    <kd value="1.0"/>
    <fdir1 value="1 0 0"/>
  </gazebo>
  <joint name="hokuyo_joint" type="fixed">
    <axis xyz="0 1 0"/>
    <origin rpy="0 0 0" xyz="0.266 0 0.04"/>
    <parent link="base_link"/>
    <child link="hokuyo_link"/>
  </joint>
  <link name="hokuyo_link">
    <inertial>
      <mass value="0.001"/>
      <origin rpy="0 0 0" xyz="0 0 0"/>
      <inertia ixx="0.0001" ixy="0" ixz="0" iyy="0.000001" iyz="0" izz="0.0001"/>
    </inertial>
    <visual>
      <origin rpy="0 0 0" xyz="0 0 0"/>
      <geometry>
        <mesh filename="/home/m-a/catkin_ws/src/gobot_simulation/gobot_description/meshes/hokuyo.dae" scale="0.024 0.024 0.024"/>
      </geometry>
    </visual>
    <collision>
      <!-- specifying a slightly too small collision surface because otherwise gazebo simulation catches on it -->
      <origin rpy="0 0 0" xyz="0 0 0.03"/>
      <geometry>
        <box size="0.02 0.02 0.06"/>
      </geometry>
    </collision>
  </link>
  <!-- go from the base of the laser to the actual sensor location -->
  <joint name="hokuyo_laser_joint" type="fixed">
    <origin xyz="0.002 0 0.0525"/>
    <!-- in segbot package was 0.058 but looking at specs it is less -->
    <parent link="hokuyo_link"/>
    <child link="hokuyo_laser_link"/>
  </joint>
  <link name="hokuyo_laser_link" type="laser">
    <inertial>
      <mass value="0.001"/>
      <origin rpy="0 0 0" xyz="0 0 0"/>
      <inertia ixx="0.0001" ixy="0" ixz="0" iyy="0.000001" iyz="0" izz="0.0001"/>
    </inertial>
  </link>
  <gazebo reference="hokuyo_laser_link">
    <sensor name="hokuyo_laser" type="ray">
      <always_on>true</always_on>
      <update_rate>20</update_rate>
      <pose>0 0 0 0 0 0</pose>
      <visualize>1</visualize>
      <ray>
        <scan>
          <horizontal>
            <samples>640</samples>
            <resolution>1</resolution>
            <min_angle>-1.57079632679</min_angle>
            <max_angle>1.57079632679</max_angle>
          </horizontal>
        </scan>
        <range>
          <min>0.02</min>
          <max>4.0</max>
          <resolution>0.03</resolution>
        </range>
        <noise>
          <type>gaussian</type>
          <!-- Noise parameters based on published spec for Hokuyo laser
            achieving "+-30mm" accuracy at range < 10m.  A mean of 0.0m and
            stddev of 0.01m will put 99.7% of samples within 0.03m of the true
            reading. 
            -->
          <mean>0.0</mean>
          <stddev>0.01</stddev>
        </noise>
      </ray>
      <plugin filename="libgazebo_ros_laser.so" name="gazebo_ros_hokuyo_laser_controller">
        <alwaysOn>true</alwaysOn>
        <updateRate>20</updateRate>
        <topicName>/scan</topicName>
        <frameName>hokuyo_link</frameName>
      </plugin>
    </sensor>
  </gazebo>
  <joint name="cliff_sensor_joint" type="fixed">
    <origin rpy="0 1.57079632679 0" xyz="0.304 -0.224 0.016"/>
    <parent link="base_link"/>
    <child link="cliff_sensor_link"/>
  </joint>
  <link name="cliff_sensor_link">
    <inertial>
      <mass value="0.001"/>
      <origin rpy="0 0 0" xyz="0 0 0"/>
      <inertia ixx="0.000000017" ixy="0" ixz="0" iyy="0.000000017" iyz="0" izz="0.000000017"/>
    </inertial>
    <visual>
      <origin rpy="0 0 0" xyz="0 0 0"/>
      <geometry>
        <!--<box size="0.01 0.01 0.01" /> -->
        <mesh filename="package://hector_sensors_description/meshes/sonar_sensor/max_sonar_ez4.dae"/>
      </geometry>
    </visual>
    <collision>
      <origin rpy="0 0 0" xyz="0 0 0"/>
      <geometry>
        <box size="0.01 0.01 0.01"/>
      </geometry>
    </collision>
  </link>
  <gazebo reference="cliff_sensor_link">
    <sensor name="cliff_sensor" type="ray">
      <always_on>true</always_on>
      <update_rate>10</update_rate>
      <visualize>true</visualize>
      <ray>
        <scan>
          <!-->
            <vertical>
              <samples>${ray_count}</samples>
              <resolution>1</resolution>
              <min_angle>${-field_of_view/2-M_PI/2}</min_angle>
              <max_angle>${field_of_view/2+M_PI/2}</max_angle>
            </vertical>
  <-->
          <horizontal>
            <samples>1</samples>
            <resolution>1</resolution>
            <min_angle>-0.025</min_angle>
            <max_angle>0.025</max_angle>
          </horizontal>
        </scan>
        <range>
          <min>0.03</min>
          <max>2.0</max>
          <resolution>0.01</resolution>
        </range>
      </ray>
      <plugin filename="libhector_gazebo_ros_sonar.so" name="gazebo_ros_cliff_sensor_controller">
        <gaussianNoise>0.03</gaussianNoise>
        <topicName>cliff_sensor_topic</topicName>
        <frameId>cliff_sensor_link</frameId>
      </plugin>
    </sensor>
  </gazebo>
  <joint name="cliff_sensor_2_joint" type="fixed">
    <origin rpy="0 1.57079632679 0" xyz="-0.304 -0.224 0.016"/>
    <parent link="base_link"/>
    <child link="cliff_sensor_2_link"/>
  </joint>
  <link name="cliff_sensor_2_link">
    <inertial>
      <mass value="0.001"/>
      <origin rpy="0 0 0" xyz="0 0 0"/>
      <inertia ixx="0.000000017" ixy="0" ixz="0" iyy="0.000000017" iyz="0" izz="0.000000017"/>
    </inertial>
    <visual>
      <origin rpy="0 0 0" xyz="0 0 0"/>
      <geometry>
        <!--<box size="0.01 0.01 0.01" /> -->
        <mesh filename="package://hector_sensors_description/meshes/sonar_sensor/max_sonar_ez4.dae"/>
      </geometry>
    </visual>
    <collision>
      <origin rpy="0 0 0" xyz="0 0 0"/>
      <geometry>
        <box size="0.01 0.01 0.01"/>
      </geometry>
    </collision>
  </link>
  <gazebo reference="cliff_sensor_2_link">
    <sensor name="cliff_sensor_2" type="ray">
      <always_on>true</always_on>
      <update_rate>10</update_rate>
      <visualize>true</visualize>
      <ray>
        <scan>
          <!-->
            <vertical>
              <samples>${ray_count}</samples>
              <resolution>1</resolution>
              <min_angle>${-field_of_view/2-M_PI/2}</min_angle>
              <max_angle>${field_of_view/2+M_PI/2}</max_angle>
            </vertical>
  <-->
          <horizontal>
            <samples>1</samples>
            <resolution>1</resolution>
            <min_angle>-0.025</min_angle>
            <max_angle>0.025</max_angle>
          </horizontal>
        </scan>
        <range>
          <min>0.01</min>
          <max>2.0</max>
          <resolution>0.01</resolution>
        </range>
      </ray>
      <plugin filename="libhector_gazebo_ros_sonar.so" name="gazebo_ros_cliff_sensor_2_controller">
        <gaussianNoise>0.03</gaussianNoise>
        <topicName>cliff_sensor_2_topic</topicName>
        <frameId>cliff_sensor_2_link</frameId>
      </plugin>
    </sensor>
  </gazebo>
  <joint name="cliff_sensor_3_joint" type="fixed">
    <origin rpy="0 1.57079632679 0" xyz="0.304 0.224 0.016"/>
    <parent link="base_link"/>
    <child link="cliff_sensor_3_link"/>
  </joint>
  <link name="cliff_sensor_3_link">
    <inertial>
      <mass value="0.001"/>
      <origin rpy="0 0 0" xyz="0 0 0"/>
      <inertia ixx="0.000000017" ixy="0" ixz="0" iyy="0.000000017" iyz="0" izz="0.000000017"/>
    </inertial>
    <visual>
      <origin rpy="0 0 0" xyz="0 0 0"/>
      <geometry>
        <!--<box size="0.01 0.01 0.01" /> -->
        <mesh filename="package://hector_sensors_description/meshes/sonar_sensor/max_sonar_ez4.dae"/>
      </geometry>
    </visual>
    <collision>
      <origin rpy="0 0 0" xyz="0 0 0"/>
      <geometry>
        <box size="0.01 0.01 0.01"/>
      </geometry>
    </collision>
  </link>
  <gazebo reference="cliff_sensor_3_link">
    <sensor name="cliff_sensor_3" type="ray">
      <always_on>true</always_on>
      <update_rate>10</update_rate>
      <visualize>true</visualize>
      <ray>
        <scan>
          <!-->
            <vertical>
              <samples>${ray_count}</samples>
              <resolution>1</resolution>
              <min_angle>${-field_of_view/2-M_PI/2}</min_angle>
              <max_angle>${field_of_view/2+M_PI/2}</max_angle>
            </vertical>
  <-->
          <horizontal>
            <samples>1</samples>
            <resolution>1</resolution>
            <min_angle>-0.025</min_angle>
            <max_angle>0.025</max_angle>
          </horizontal>
        </scan>
        <range>
          <min>0.01</min>
          <max>2.0</max>
          <resolution>0.01</resolution>
        </range>
      </ray>
      <plugin filename="libhector_gazebo_ros_sonar.so" name="gazebo_ros_cliff_sensor_3_controller">
        <gaussianNoise>0.03</gaussianNoise>
        <topicName>cliff_sensor_3_topic</topicName>
        <frameId>cliff_sensor_3_link</frameId>
      </plugin>
    </sensor>
  </gazebo>
  <joint name="cliff_sensor_4_joint" type="fixed">
    <origin rpy="0 1.57079632679 0" xyz="-0.304 0.224 0.016"/>
    <parent link="base_link"/>
    <child link="cliff_sensor_4_link"/>
  </joint>
  <link name="cliff_sensor_4_link">
    <inertial>
      <mass value="0.001"/>
      <origin rpy="0 0 0" xyz="0 0 0"/>
      <inertia ixx="0.000000017" ixy="0" ixz="0" iyy="0.000000017" iyz="0" izz="0.000000017"/>
    </inertial>
    <visual>
      <origin rpy="0 0 0" xyz="0 0 0"/>
      <geometry>
        <!--<box size="0.01 0.01 0.01" /> -->
        <mesh filename="package://hector_sensors_description/meshes/sonar_sensor/max_sonar_ez4.dae"/>
      </geometry>
    </visual>
    <collision>
      <origin rpy="0 0 0" xyz="0 0 0"/>
      <geometry>
        <box size="0.01 0.01 0.01"/>
      </geometry>
    </collision>
  </link>
  <gazebo reference="cliff_sensor_4_link">
    <sensor name="cliff_sensor_4" type="ray">
      <always_on>true</always_on>
      <update_rate>10</update_rate>
      <visualize>true</visualize>
      <ray>
        <scan>
          <!-->
            <vertical>
              <samples>${ray_count}</samples>
              <resolution>1</resolution>
              <min_angle>${-field_of_view/2-M_PI/2}</min_angle>
              <max_angle>${field_of_view/2+M_PI/2}</max_angle>
            </vertical>
  <-->
          <horizontal>
            <samples>1</samples>
            <resolution>1</resolution>
            <min_angle>-0.025</min_angle>
            <max_angle>0.025</max_angle>
          </horizontal>
        </scan>
        <range>
          <min>0.01</min>
          <max>2.0</max>
          <resolution>0.01</resolution>
        </range>
      </ray>
      <plugin filename="libhector_gazebo_ros_sonar.so" name="gazebo_ros_cliff_sensor_4_controller">
        <gaussianNoise>0.03</gaussianNoise>
        <topicName>cliff_sensor_4_topic</topicName>
        <frameId>cliff_sensor_4_link</frameId>
      </plugin>
    </sensor>
  </gazebo>
  <joint name="sonar_E0_joint" type="fixed">
    <origin rpy="0 0 3.14159265359" xyz="-0.324 -0.065 0.08"/>
    <parent link="base_link"/>
    <child link="sonar_E0_link"/>
  </joint>
  <link name="sonar_E0_link">
    <inertial>
      <mass value="0.001"/>
      <origin rpy="0 0 0" xyz="0 0 0"/>
      <inertia ixx="0.000000017" ixy="0" ixz="0" iyy="0.000000017" iyz="0" izz="0.000000017"/>
    </inertial>
    <visual>
      <origin rpy="0 0 0" xyz="0 0 0"/>
      <geometry>
        <!--<box size="0.01 0.01 0.01" /> -->
        <mesh filename="package://hector_sensors_description/meshes/sonar_sensor/max_sonar_ez4.dae"/>
      </geometry>
    </visual>
    <collision>
      <origin rpy="0 0 0" xyz="0 0 0"/>
      <geometry>
        <box size="0.01 0.01 0.01"/>
      </geometry>
    </collision>
  </link>
  <gazebo reference="sonar_E0_link">
    <sensor name="sonar_E0" type="ray">
      <always_on>true</always_on>
      <update_rate>20</update_rate>
      <visualize>false</visualize>
      <ray>
        <scan>
          <horizontal>
            <samples>60</samples>
            <resolution>1</resolution>
            <min_angle>-0.5236</min_angle>
            <max_angle>0.5236</max_angle>
          </horizontal>
        </scan>
        <range>
          <min>0.15</min>
          <max>6.0</max>
          <resolution>0.03</resolution>
        </range>
      </ray>
      <plugin filename="libhector_gazebo_ros_sonar.so" name="gazebo_ros_sonar_E0_controller">
        <gaussianNoise>0.03</gaussianNoise>
        <topicName>/sensors/sonar_sensor/sonar_zero_range</topicName>
        <frameId>sonar_E0_link</frameId>
      </plugin>
    </sensor>
  </gazebo>
  <joint name="sonar_E6_joint" type="fixed">
    <origin rpy="0 0 1.57079632679" xyz="-0.009 0.2995 0.088"/>
    <parent link="base_link"/>
    <child link="sonar_E6_link"/>
  </joint>
  <link name="sonar_E6_link">
    <inertial>
      <mass value="0.001"/>
      <origin rpy="0 0 0" xyz="0 0 0"/>
      <inertia ixx="0.000000017" ixy="0" ixz="0" iyy="0.000000017" iyz="0" izz="0.000000017"/>
    </inertial>
    <visual>
      <origin rpy="0 0 0" xyz="0 0 0"/>
      <geometry>
        <!--<box size="0.01 0.01 0.01" /> -->
        <mesh filename="package://hector_sensors_description/meshes/sonar_sensor/max_sonar_ez4.dae"/>
      </geometry>
    </visual>
    <collision>
      <origin rpy="0 0 0" xyz="0 0 0"/>
      <geometry>
        <box size="0.01 0.01 0.01"/>
      </geometry>
    </collision>
  </link>
  <gazebo reference="sonar_E6_link">
    <sensor name="sonar_E6" type="ray">
      <always_on>true</always_on>
      <update_rate>20</update_rate>
      <visualize>false</visualize>
      <ray>
        <scan>
          <horizontal>
            <samples>60</samples>
            <resolution>1</resolution>
            <min_angle>-0.5236</min_angle>
            <max_angle>0.5236</max_angle>
          </horizontal>
        </scan>
        <range>
          <min>0.15</min>
          <max>6.0</max>
          <resolution>0.03</resolution>
        </range>
      </ray>
      <plugin filename="libhector_gazebo_ros_sonar.so" name="gazebo_ros_sonar_E6_controller">
        <gaussianNoise>0.03</gaussianNoise>
        <topicName>/sensors/sonar_sensor/sonar_six_range</topicName>
        <frameId>sonar_E6_link</frameId>
      </plugin>
    </sensor>
  </gazebo>
  <joint name="sonar_E8_joint" type="fixed">
    <origin rpy="0 0 4.71238898038" xyz="-0.009 -0.2995 0.088"/>
    <parent link="base_link"/>
    <child link="sonar_E8_link"/>
  </joint>
  <link name="sonar_E8_link">
    <inertial>
      <mass value="0.001"/>
      <origin rpy="0 0 0" xyz="0 0 0"/>
      <inertia ixx="0.000000017" ixy="0" ixz="0" iyy="0.000000017" iyz="0" izz="0.000000017"/>
    </inertial>
    <visual>
      <origin rpy="0 0 0" xyz="0 0 0"/>
      <geometry>
        <!--<box size="0.01 0.01 0.01" /> -->
        <mesh filename="package://hector_sensors_description/meshes/sonar_sensor/max_sonar_ez4.dae"/>
      </geometry>
    </visual>
    <collision>
      <origin rpy="0 0 0" xyz="0 0 0"/>
      <geometry>
        <box size="0.01 0.01 0.01"/>
      </geometry>
    </collision>
  </link>
  <gazebo reference="sonar_E8_link">
    <sensor name="sonar_E8" type="ray">
      <always_on>true</always_on>
      <update_rate>20</update_rate>
      <visualize>false</visualize>
      <ray>
        <scan>
          <horizontal>
            <samples>60</samples>
            <resolution>1</resolution>
            <min_angle>-0.5236</min_angle>
            <max_angle>0.5236</max_angle>
          </horizontal>
        </scan>
        <range>
          <min>0.15</min>
          <max>6.0</max>
          <resolution>0.03</resolution>
        </range>
      </ray>
      <plugin filename="libhector_gazebo_ros_sonar.so" name="gazebo_ros_sonar_E8_controller">
        <gaussianNoise>0.03</gaussianNoise>
        <topicName>/sensors/sonar_sensor/sonar_eight_range</topicName>
        <frameId>sonar_E8_link</frameId>
      </plugin>
    </sensor>
  </gazebo>
  <joint name="sonar_E2_joint" type="fixed">
    <origin rpy="0 0 0.0" xyz="0.324 -0.07 0.128"/>
    <parent link="base_link"/>
    <child link="sonar_E2_link"/>
  </joint>
  <link name="sonar_E2_link">
    <inertial>
      <mass value="0.001"/>
      <origin rpy="0 0 0" xyz="0 0 0"/>
      <inertia ixx="0.000000017" ixy="0" ixz="0" iyy="0.000000017" iyz="0" izz="0.000000017"/>
    </inertial>
    <visual>
      <origin rpy="0 0 0" xyz="0 0 0"/>
      <geometry>
        <!--<box size="0.01 0.01 0.01" /> -->
        <mesh filename="package://hector_sensors_description/meshes/sonar_sensor/max_sonar_ez4.dae"/>
      </geometry>
    </visual>
    <collision>
      <origin rpy="0 0 0" xyz="0 0 0"/>
      <geometry>
        <box size="0.01 0.01 0.01"/>
      </geometry>
    </collision>
  </link>
  <gazebo reference="sonar_E2_link">
    <sensor name="sonar_E2" type="ray">
      <always_on>true</always_on>
      <update_rate>20</update_rate>
      <visualize>false</visualize>
      <ray>
        <scan>
          <horizontal>
            <samples>60</samples>
            <resolution>1</resolution>
            <min_angle>-0.5236</min_angle>
            <max_angle>0.5236</max_angle>
          </horizontal>
        </scan>
        <range>
          <min>0.15</min>
          <max>6.0</max>
          <resolution>0.03</resolution>
        </range>
      </ray>
      <plugin filename="libhector_gazebo_ros_sonar.so" name="gazebo_ros_sonar_E2_controller">
        <gaussianNoise>0.03</gaussianNoise>
        <topicName>/sensors/sonar_sensor/sonar_two_range</topicName>
        <frameId>sonar_E2_link</frameId>
      </plugin>
    </sensor>
  </gazebo>
  <joint name="sonar_E4_joint" type="fixed">
    <origin rpy="0 0 0.0" xyz="0.324 0.07 0.128"/>
    <parent link="base_link"/>
    <child link="sonar_E4_link"/>
  </joint>
  <link name="sonar_E4_link">
    <inertial>
      <mass value="0.001"/>
      <origin rpy="0 0 0" xyz="0 0 0"/>
      <inertia ixx="0.000000017" ixy="0" ixz="0" iyy="0.000000017" iyz="0" izz="0.000000017"/>
    </inertial>
    <visual>
      <origin rpy="0 0 0" xyz="0 0 0"/>
      <geometry>
        <!--<box size="0.01 0.01 0.01" /> -->
        <mesh filename="package://hector_sensors_description/meshes/sonar_sensor/max_sonar_ez4.dae"/>
      </geometry>
    </visual>
    <collision>
      <origin rpy="0 0 0" xyz="0 0 0"/>
      <geometry>
        <box size="0.01 0.01 0.01"/>
      </geometry>
    </collision>
  </link>
  <gazebo reference="sonar_E4_link">
    <sensor name="sonar_E4" type="ray">
      <always_on>true</always_on>
      <update_rate>20</update_rate>
      <visualize>false</visualize>
      <ray>
        <scan>
          <horizontal>
            <samples>60</samples>
            <resolution>1</resolution>
            <min_angle>-0.5236</min_angle>
            <max_angle>0.5236</max_angle>
          </horizontal>
        </scan>
        <range>
          <min>0.15</min>
          <max>6.0</max>
          <resolution>0.03</resolution>
        </range>
      </ray>
      <plugin filename="libhector_gazebo_ros_sonar.so" name="gazebo_ros_sonar_E4_controller">
        <gaussianNoise>0.03</gaussianNoise>
        <topicName>/sensors/sonar_sensor/sonar_four_range</topicName>
        <frameId>sonar_E4_link</frameId>
      </plugin>
    </sensor>
  </gazebo>
  <link name="rear_1_wall_link">
    <inertial>
      <mass value="0.001"/>
      <origin rpy="0 0 0" xyz="0 0 0"/>
      <inertia ixx="0.000000017" ixy="0" ixz="0" iyy="0.000000017" iyz="0" izz="0.000000017"/>
    </inertial>
    <visual>
      <origin rpy="0 0 0" xyz="0 0 0"/>
      <geometry>
        <box size="0.0001 0.005 0.005"/>
      </geometry>
      <cast_shadows>0</cast_shadows>
    </visual>
    <collision>
      <origin rpy="0 0 0" xyz="0 0 0"/>
      <geometry>
        <box size="0.0001 0.005 0.005"/>
      </geometry>
    </collision>
  </link>
  <link name="rear_1_link">
    <inertial>
      <mass value="0.001"/>
      <origin rpy="0 0 0" xyz="0 0 0"/>
      <inertia ixx="0.000000017" ixy="0" ixz="0" iyy="0.000000017" iyz="0" izz="0.000000017"/>
    </inertial>
    <visual>
      <origin rpy="0 0 0" xyz="0 0 0"/>
      <geometry>
        <box size="0.00001 0.00001 0.00001"/>
      </geometry>
      <cast_shadows>0</cast_shadows>
    </visual>
    <collision>
      <origin rpy="0 0 0" xyz="0 0 0"/>
      <geometry>
        <box size="0.00001 0.00001 0.00001"/>
      </geometry>
    </collision>
  </link>
  <link name="rear_2_wall_link">
    <inertial>
      <mass value="0.001"/>
      <origin rpy="0 0 0" xyz="0 0 0"/>
      <inertia ixx="0.000000017" ixy="0" ixz="0" iyy="0.000000017" iyz="0" izz="0.000000017"/>
    </inertial>
    <visual>
      <origin rpy="0 0 0" xyz="0 0 0"/>
      <geometry>
        <box size="0.0001 0.005 0.005"/>
      </geometry>
      <cast_shadows>0</cast_shadows>
    </visual>
    <collision>
      <origin rpy="0 0 0" xyz="0 0 0"/>
      <geometry>
        <box size="0.0001 0.005 0.005"/>
      </geometry>
    </collision>
  </link>
  <link name="rear_2_link">
    <inertial>
      <mass value="0.001"/>
      <origin rpy="0 0 0" xyz="0 0 0"/>
      <inertia ixx="0.000000017" ixy="0" ixz="0" iyy="0.000000017" iyz="0" izz="0.000000017"/>
    </inertial>
    <visual>
      <origin rpy="0 0 0" xyz="0 0 0"/>
      <geometry>
        <box size="0.00001 0.00001 0.00001"/>
      </geometry>
      <cast_shadows>0</cast_shadows>
    </visual>
    <collision>
      <origin rpy="0 0 0" xyz="0 0 0"/>
      <geometry>
        <box size="0.00001 0.00001 0.00001"/>
      </geometry>
    </collision>
  </link>
  <joint name="rear_1_joint_wall" type="fixed">
    <origin rpy="0 0 0" xyz="-0.00008 0 0"/>
    <parent link="rear_1_wall_link"/>
    <child link="rear_1_link"/>
  </joint>
  <joint name="rear_2_joint_wall" type="fixed">
    <origin rpy="0 0 0" xyz="-0.00008 0 0"/>
    <parent link="rear_2_wall_link"/>
    <child link="rear_2_link"/>
  </joint>
  <joint name="rear_1_joint" type="fixed">
    <origin rpy="0 0 1.4398966329" xyz="-0.326478612153 0.00032631548055 0.126"/>
    <parent link="base_link"/>
    <child link="rear_1_wall_link"/>
  </joint>
  <joint name="rear_2_joint" type="fixed">
    <origin rpy="0 0 -1.4398966329" xyz="-0.326478612153 -0.00032631548055 0.126"/>
    <parent link="base_link"/>
    <child link="rear_2_wall_link"/>
  </joint>
  <gazebo reference="rear_1_wall_link">
    <material>Gazebo/Grey</material>
  </gazebo>
  <gazebo reference="rear_1_link">
    <material>Gazebo/White</material>
    <sensor name="camera" type="camera">
      <camera name="__default__">
        <horizontal_fov>0.1</horizontal_fov>
        <image>
          <width>1</width>
          <height>1</height>
        </image>
        <clip>
          <near>0.00001</near>
          <far>100</far>
        </clip>
      </camera>
      <plugin filename="libgazebo_ros_camera.so" name="ir_controller">
        <cameraName>rear_1_camera</cameraName>
        <alwaysOn>true</alwaysOn>
        <updateRate>10</updateRate>
        <imageTopicName>rgb/image_raw</imageTopicName>
        <cameraInfoTopicName>rgb/camera_info</cameraInfoTopicName>
        <frameName>rear_1_link</frameName>
        <hackBaseline>0.07</hackBaseline>
        <distortionK1>0.0</distortionK1>
        <distortionK2>0.0</distortionK2>
        <distortionK3>0.0</distortionK3>
        <distortionT1>0.0</distortionT1>
        <distortionT2>0.0</distortionT2>
      </plugin>
    </sensor>
  </gazebo>
  <gazebo reference="rear_2_wall_link">
    <material>Gazebo/Grey</material>
  </gazebo>
  <gazebo reference="rear_2_link">
    <material>Gazebo/White</material>
    <sensor name="camera" type="camera">
      <camera name="__default__">
        <horizontal_fov>0.1</horizontal_fov>
        <image>
          <width>1</width>
          <height>1</height>
        </image>
        <clip>
          <near>0.00001</near>
          <far>100</far>
        </clip>
      </camera>
      <plugin filename="libgazebo_ros_camera.so" name="ir_controller">
        <cameraName>rear_2_camera</cameraName>
        <alwaysOn>true</alwaysOn>
        <updateRate>10</updateRate>
        <imageTopicName>rgb/image_raw</imageTopicName>
        <cameraInfoTopicName>rgb/camera_info</cameraInfoTopicName>
        <frameName>rear_2_link</frameName>
        <hackBaseline>0.07</hackBaseline>
        <distortionK1>0.0</distortionK1>
        <distortionK2>0.0</distortionK2>
        <distortionK3>0.0</distortionK3>
        <distortionT1>0.0</distortionT1>
        <distortionT2>0.0</distortionT2>
      </plugin>
    </sensor>
  </gazebo>
  <link name="right_1_wall_link">
    <inertial>
      <mass value="0.001"/>
      <origin rpy="0 0 0" xyz="0 0 0"/>
      <inertia ixx="0.000000017" ixy="0" ixz="0" iyy="0.000000017" iyz="0" izz="0.000000017"/>
    </inertial>
    <visual>
      <origin rpy="0 0 0" xyz="0 0 0"/>
      <geometry>
        <box size="0.0001 0.005 0.005"/>
      </geometry>
      <cast_shadows>0</cast_shadows>
    </visual>
    <collision>
      <origin rpy="0 0 0" xyz="0 0 0"/>
      <geometry>
        <box size="0.0001 0.005 0.005"/>
      </geometry>
    </collision>
  </link>
  <link name="right_1_link">
    <inertial>
      <mass value="0.001"/>
      <origin rpy="0 0 0" xyz="0 0 0"/>
      <inertia ixx="0.000000017" ixy="0" ixz="0" iyy="0.000000017" iyz="0" izz="0.000000017"/>
    </inertial>
    <visual>
      <origin rpy="0 0 0" xyz="0 0 0"/>
      <geometry>
        <box size="0.00001 0.00001 0.00001"/>
      </geometry>
      <cast_shadows>0</cast_shadows>
    </visual>
    <collision>
      <origin rpy="0 0 0" xyz="0 0 0"/>
      <geometry>
        <box size="0.00001 0.00001 0.00001"/>
      </geometry>
    </collision>
  </link>
  <link name="right_2_wall_link">
    <inertial>
      <mass value="0.001"/>
      <origin rpy="0 0 0" xyz="0 0 0"/>
      <inertia ixx="0.000000017" ixy="0" ixz="0" iyy="0.000000017" iyz="0" izz="0.000000017"/>
    </inertial>
    <visual>
      <origin rpy="0 0 0" xyz="0 0 0"/>
      <geometry>
        <box size="0.0001 0.005 0.005"/>
      </geometry>
      <cast_shadows>0</cast_shadows>
    </visual>
    <collision>
      <origin rpy="0 0 0" xyz="0 0 0"/>
      <geometry>
        <box size="0.0001 0.005 0.005"/>
      </geometry>
    </collision>
  </link>
  <link name="right_2_link">
    <inertial>
      <mass value="0.001"/>
      <origin rpy="0 0 0" xyz="0 0 0"/>
      <inertia ixx="0.000000017" ixy="0" ixz="0" iyy="0.000000017" iyz="0" izz="0.000000017"/>
    </inertial>
    <visual>
      <origin rpy="0 0 0" xyz="0 0 0"/>
      <geometry>
        <box size="0.00001 0.00001 0.00001"/>
      </geometry>
      <cast_shadows>0</cast_shadows>
    </visual>
    <collision>
      <origin rpy="0 0 0" xyz="0 0 0"/>
      <geometry>
        <box size="0.00001 0.00001 0.00001"/>
      </geometry>
    </collision>
  </link>
  <joint name="right_1_joint_wall" type="fixed">
    <origin rpy="0 0 0" xyz="-0.00008 0 0"/>
    <parent link="right_1_wall_link"/>
    <child link="right_1_link"/>
  </joint>
  <joint name="right_2_joint_wall" type="fixed">
    <origin rpy="0 0 0" xyz="-0.00008 0 0"/>
    <parent link="right_2_wall_link"/>
    <child link="right_2_link"/>
  </joint>
  <joint name="right_1_joint" type="fixed">
    <origin rpy="0 0 2.74889357189" xyz="-0.000956708580913 -0.301809698831 0.126"/>
    <parent link="base_link"/>
    <child link="right_1_wall_link"/>
  </joint>
  <joint name="right_2_joint" type="fixed">
    <origin rpy="0 0 0.392699081699" xyz="0.000956708580913 -0.301809698831 0.126"/>
    <parent link="base_link"/>
    <child link="right_2_wall_link"/>
  </joint>
  <gazebo reference="right_1_wall_link">
    <material>Gazebo/Grey</material>
  </gazebo>
  <gazebo reference="right_1_link">
    <material>Gazebo/White</material>
    <sensor name="camera" type="camera">
      <camera name="__default__">
        <horizontal_fov>0.1</horizontal_fov>
        <image>
          <width>1</width>
          <height>1</height>
        </image>
        <clip>
          <near>0.00001</near>
          <far>100</far>
        </clip>
      </camera>
      <plugin filename="libgazebo_ros_camera.so" name="ir_controller">
        <cameraName>right_1_camera</cameraName>
        <alwaysOn>true</alwaysOn>
        <updateRate>10</updateRate>
        <imageTopicName>rgb/image_raw</imageTopicName>
        <cameraInfoTopicName>rgb/camera_info</cameraInfoTopicName>
        <frameName>right_1_link</frameName>
        <hackBaseline>0.07</hackBaseline>
        <distortionK1>0.0</distortionK1>
        <distortionK2>0.0</distortionK2>
        <distortionK3>0.0</distortionK3>
        <distortionT1>0.0</distortionT1>
        <distortionT2>0.0</distortionT2>
      </plugin>
    </sensor>
  </gazebo>
  <gazebo reference="right_2_wall_link">
    <material>Gazebo/Grey</material>
  </gazebo>
  <gazebo reference="right_2_link">
    <material>Gazebo/White</material>
    <sensor name="camera" type="camera">
      <camera name="__default__">
        <horizontal_fov>0.1</horizontal_fov>
        <image>
          <width>1</width>
          <height>1</height>
        </image>
        <clip>
          <near>0.00001</near>
          <far>100</far>
        </clip>
      </camera>
      <plugin filename="libgazebo_ros_camera.so" name="ir_controller">
        <cameraName>right_2_camera</cameraName>
        <alwaysOn>true</alwaysOn>
        <updateRate>10</updateRate>
        <imageTopicName>rgb/image_raw</imageTopicName>
        <cameraInfoTopicName>rgb/camera_info</cameraInfoTopicName>
        <frameName>right_2_link</frameName>
        <hackBaseline>0.07</hackBaseline>
        <distortionK1>0.0</distortionK1>
        <distortionK2>0.0</distortionK2>
        <distortionK3>0.0</distortionK3>
        <distortionT1>0.0</distortionT1>
        <distortionT2>0.0</distortionT2>
      </plugin>
    </sensor>
  </gazebo>
  <link name="left_1_wall_link">
    <inertial>
      <mass value="0.001"/>
      <origin rpy="0 0 0" xyz="0 0 0"/>
      <inertia ixx="0.000000017" ixy="0" ixz="0" iyy="0.000000017" iyz="0" izz="0.000000017"/>
    </inertial>
    <visual>
      <origin rpy="0 0 0" xyz="0 0 0"/>
      <geometry>
        <box size="0.0001 0.005 0.005"/>
      </geometry>
      <cast_shadows>0</cast_shadows>
    </visual>
    <collision>
      <origin rpy="0 0 0" xyz="0 0 0"/>
      <geometry>
        <box size="0.0001 0.005 0.005"/>
      </geometry>
    </collision>
  </link>
  <link name="left_1_link">
    <inertial>
      <mass value="0.001"/>
      <origin rpy="0 0 0" xyz="0 0 0"/>
      <inertia ixx="0.000000017" ixy="0" ixz="0" iyy="0.000000017" iyz="0" izz="0.000000017"/>
    </inertial>
    <visual>
      <origin rpy="0 0 0" xyz="0 0 0"/>
      <geometry>
        <box size="0.00001 0.00001 0.00001"/>
      </geometry>
      <cast_shadows>0</cast_shadows>
    </visual>
    <collision>
      <origin rpy="0 0 0" xyz="0 0 0"/>
      <geometry>
        <box size="0.00001 0.00001 0.00001"/>
      </geometry>
    </collision>
  </link>
  <link name="left_2_wall_link">
    <inertial>
      <mass value="0.001"/>
      <origin rpy="0 0 0" xyz="0 0 0"/>
      <inertia ixx="0.000000017" ixy="0" ixz="0" iyy="0.000000017" iyz="0" izz="0.000000017"/>
    </inertial>
    <visual>
      <origin rpy="0 0 0" xyz="0 0 0"/>
      <geometry>
        <box size="0.0001 0.005 0.005"/>
      </geometry>
      <cast_shadows>0</cast_shadows>
    </visual>
    <collision>
      <origin rpy="0 0 0" xyz="0 0 0"/>
      <geometry>
        <box size="0.0001 0.005 0.005"/>
      </geometry>
    </collision>
  </link>
  <link name="left_2_link">
    <inertial>
      <mass value="0.001"/>
      <origin rpy="0 0 0" xyz="0 0 0"/>
      <inertia ixx="0.000000017" ixy="0" ixz="0" iyy="0.000000017" iyz="0" izz="0.000000017"/>
    </inertial>
    <visual>
      <origin rpy="0 0 0" xyz="0 0 0"/>
      <geometry>
        <box size="0.00001 0.00001 0.00001"/>
      </geometry>
      <cast_shadows>0</cast_shadows>
    </visual>
    <collision>
      <origin rpy="0 0 0" xyz="0 0 0"/>
      <geometry>
        <box size="0.00001 0.00001 0.00001"/>
      </geometry>
    </collision>
  </link>
  <joint name="left_1_joint_wall" type="fixed">
    <origin rpy="0 0 0" xyz="-0.00008 0 0"/>
    <parent link="left_1_wall_link"/>
    <child link="left_1_link"/>
  </joint>
  <joint name="left_2_joint_wall" type="fixed">
    <origin rpy="0 0 0" xyz="-0.00008 0 0"/>
    <parent link="left_2_wall_link"/>
    <child link="left_2_link"/>
  </joint>
  <joint name="left_1_joint" type="fixed">
    <origin rpy="0 0 5.89048622548" xyz="0.000956708580913 0.301809698831 0.126"/>
    <parent link="base_link"/>
    <child link="left_1_wall_link"/>
  </joint>
  <joint name="left_2_joint" type="fixed">
    <origin rpy="0 0 3.53429173529" xyz="-0.000956708580913 0.301809698831 0.126"/>
    <parent link="base_link"/>
    <child link="left_2_wall_link"/>
  </joint>
  <gazebo reference="left_1_wall_link">
    <material>Gazebo/Grey</material>
  </gazebo>
  <gazebo reference="left_1_link">
    <material>Gazebo/White</material>
    <sensor name="camera" type="camera">
      <camera name="__default__">
        <horizontal_fov>0.1</horizontal_fov>
        <image>
          <width>1</width>
          <height>1</height>
        </image>
        <clip>
          <near>0.00001</near>
          <far>100</far>
        </clip>
      </camera>
      <plugin filename="libgazebo_ros_camera.so" name="ir_controller">
        <cameraName>left_1_camera</cameraName>
        <alwaysOn>true</alwaysOn>
        <updateRate>10</updateRate>
        <imageTopicName>rgb/image_raw</imageTopicName>
        <cameraInfoTopicName>rgb/camera_info</cameraInfoTopicName>
        <frameName>left_1_link</frameName>
        <hackBaseline>0.07</hackBaseline>
        <distortionK1>0.0</distortionK1>
        <distortionK2>0.0</distortionK2>
        <distortionK3>0.0</distortionK3>
        <distortionT1>0.0</distortionT1>
        <distortionT2>0.0</distortionT2>
      </plugin>
    </sensor>
  </gazebo>
  <gazebo reference="left_2_wall_link">
    <material>Gazebo/Grey</material>
  </gazebo>
  <gazebo reference="left_2_link">
    <material>Gazebo/White</material>
    <sensor name="camera" type="camera">
      <camera name="__default__">
        <horizontal_fov>0.1</horizontal_fov>
        <image>
          <width>1</width>
          <height>1</height>
        </image>
        <clip>
          <near>0.00001</near>
          <far>100</far>
        </clip>
      </camera>
      <plugin filename="libgazebo_ros_camera.so" name="ir_controller">
        <cameraName>left_2_camera</cameraName>
        <alwaysOn>true</alwaysOn>
        <updateRate>10</updateRate>
        <imageTopicName>rgb/image_raw</imageTopicName>
        <cameraInfoTopicName>rgb/camera_info</cameraInfoTopicName>
        <frameName>left_2_link</frameName>
        <hackBaseline>0.07</hackBaseline>
        <distortionK1>0.0</distortionK1>
        <distortionK2>0.0</distortionK2>
        <distortionK3>0.0</distortionK3>
        <distortionT1>0.0</distortionT1>
        <distortionT2>0.0</distortionT2>
      </plugin>
    </sensor>
  </gazebo>
  <joint name="prox_left_joint" type="fixed">
    <origin rpy="0 0 3.14159265359" xyz="-0.324 0.085 0.15"/>
    <parent link="base_link"/>
    <child link="prox_left_link"/>
  </joint>
  <link name="prox_left_link">
    <inertial>
      <mass value="0.001"/>
      <origin rpy="0 0 0" xyz="0 0 0"/>
      <inertia ixx="0.000000017" ixy="0" ixz="0" iyy="0.000000017" iyz="0" izz="0.000000017"/>
    </inertial>
    <visual>
      <origin rpy="0 0 0" xyz="0 0 0"/>
      <geometry>
        <!--<box size="0.01 0.01 0.01" /> -->
        <mesh filename="package://hector_sensors_description/meshes/sonar_sensor/max_sonar_ez4.dae"/>
      </geometry>
    </visual>
    <collision>
      <origin rpy="0 0 0" xyz="0 0 0"/>
      <geometry>
        <box size="0.01 0.01 0.01"/>
      </geometry>
    </collision>
  </link>
  <gazebo reference="prox_left_link">
    <sensor name="prox_left" type="ray">
      <always_on>true</always_on>
      <update_rate>20</update_rate>
      <visualize>1</visualize>
      <ray>
        <scan>
          <horizontal>
            <samples>1</samples>
            <resolution>1</resolution>
            <min_angle>-0.025</min_angle>
            <max_angle>0.025</max_angle>
          </horizontal>
        </scan>
        <range>
          <min>0.05</min>
          <max>0.15</max>
          <resolution>0.01</resolution>
        </range>
      </ray>
      <plugin filename="libhector_gazebo_ros_sonar.so" name="gazebo_ros_prox_left_controller">
        <gaussianNoise>0.0</gaussianNoise>
        <topicName>/sensors/sonar_sensor/proximity_left</topicName>
        <frameId>prox_left_link</frameId>
      </plugin>
    </sensor>
  </gazebo>
  <joint name="prox_right_joint" type="fixed">
    <origin rpy="0 0 3.14159265359" xyz="-0.324 -0.085 0.15"/>
    <parent link="base_link"/>
    <child link="prox_right_link"/>
  </joint>
  <link name="prox_right_link">
    <inertial>
      <mass value="0.001"/>
      <origin rpy="0 0 0" xyz="0 0 0"/>
      <inertia ixx="0.000000017" ixy="0" ixz="0" iyy="0.000000017" iyz="0" izz="0.000000017"/>
    </inertial>
    <visual>
      <origin rpy="0 0 0" xyz="0 0 0"/>
      <geometry>
        <!--<box size="0.01 0.01 0.01" /> -->
        <mesh filename="package://hector_sensors_description/meshes/sonar_sensor/max_sonar_ez4.dae"/>
      </geometry>
    </visual>
    <collision>
      <origin rpy="0 0 0" xyz="0 0 0"/>
      <geometry>
        <box size="0.01 0.01 0.01"/>
      </geometry>
    </collision>
  </link>
  <gazebo reference="prox_right_link">
    <sensor name="prox_right" type="ray">
      <always_on>true</always_on>
      <update_rate>20</update_rate>
      <visualize>1</visualize>
      <ray>
        <scan>
          <horizontal>
            <samples>1</samples>
            <resolution>1</resolution>
            <min_angle>-0.025</min_angle>
            <max_angle>0.025</max_angle>
          </horizontal>
        </scan>
        <range>
          <min>0.05</min>
          <max>0.15</max>
          <resolution>0.01</resolution>
        </range>
      </ray>
      <plugin filename="libhector_gazebo_ros_sonar.so" name="gazebo_ros_prox_right_controller">
        <gaussianNoise>0.0</gaussianNoise>
        <topicName>/sensors/sonar_sensor/proximity_right</topicName>
        <frameId>prox_right_link</frameId>
      </plugin>
    </sensor>
  </gazebo>
  <link name="left_battery">
    <visual>
      <origin rpy="0 0 0" xyz="0 0 0"/>
      <geometry>
        <cylinder length="0.015" radius="0.0165"/>
      </geometry>
    </visual>
    <collision>
      <origin rpy="0 0 0" xyz="0 0 0"/>
      <geometry>
        <cylinder length="0.015" radius="0.0165"/>
      </geometry>
    </collision>
    <inertial>
      <mass value="0.1"/>
      <origin xyz="0 0 0"/>
      <inertia ixx="8.68125e-06" ixy="0" ixz="0" iyy="8.68125e-06" iyz="0" izz="1.36125e-05"/>
    </inertial>
  </link>
  <joint name="left_battery_joint" type="prismatic">
    <parent link="base_link"/>
    <child link="left_battery"/>
    <origin rpy="1.57079632679 0 0" xyz="-0.244 0.049 0.025"/>
    <axis xyz="0 1 0"/>
    <limit effort="1000.0" lower="0" upper="0.2" velocity="0.5"/>
  </joint>
  <gazebo reference="left_battery">
    <material>Gazebo/Black</material>
    <sensor name="left_battery_sensor" type="contact">
      <contact>
        <collision>left_battery_collision</collision>
      </contact>
      <plugin filename="libgazebo_ros_bumper.so" name="left_battery_gazebo_ros_bumper_controller">
        <alwaysOn>true</alwaysOn>
        <updateRate>20</updateRate>
        <bumperTopicName>left_battery</bumperTopicName>
        <frameName>world</frameName>
      </plugin>
    </sensor>
  </gazebo>
  <link name="right_battery">
    <visual>
      <origin rpy="0 0 0" xyz="0 0 0"/>
      <geometry>
        <cylinder length="0.015" radius="0.0165"/>
      </geometry>
    </visual>
    <collision>
      <origin rpy="0 0 0" xyz="0 0 0"/>
      <geometry>
        <cylinder length="0.015" radius="0.0165"/>
      </geometry>
    </collision>
    <inertial>
      <mass value="0.1"/>
      <origin xyz="0 0 0"/>
      <inertia ixx="8.68125e-06" ixy="0" ixz="0" iyy="8.68125e-06" iyz="0" izz="1.36125e-05"/>
    </inertial>
  </link>
  <joint name="right_battery_joint" type="prismatic">
    <parent link="base_link"/>
    <child link="right_battery"/>
    <origin rpy="1.57079632679 0 0" xyz="-0.244 -0.049 0.025"/>
    <axis xyz="0 1 0"/>
    <limit effort="1000.0" lower="0" upper="0.2" velocity="0.5"/>
  </joint>
  <gazebo reference="right_battery">
    <material>Gazebo/Black</material>
    <sensor name="right_battery_sensor" type="contact">
      <contact>
        <collision>right_battery_collision</collision>
      </contact>
      <plugin filename="libgazebo_ros_bumper.so" name="right_battery_gazebo_ros_bumper_controller">
        <alwaysOn>true</alwaysOn>
        <updateRate>20</updateRate>
        <bumperTopicName>right_battery</bumperTopicName>
        <frameName>world</frameName>
      </plugin>
    </sensor>
  </gazebo>
</robot>
