<?xml version="1.0"?>
<robot name="battery" xmlns:xacro="http://ros.org/wiki/xacro">
    <xacro:include filename="$(find gobot_description)/urdf/bumper/bumper.gazebo.xacro" />

    <xacro:macro name="battery" params="name parent height radius translateX translateY translateZ rotationX collision update_rate">
        <link name="${name}">
            <visual>
                <origin xyz="0 0 0" rpy="0 0 0" /> 
                <geometry>
                    <cylinder length="${height}" radius="${radius}" />
                </geometry>
            </visual>
            <collision>
                <origin xyz="0 0 0" rpy="0 0 0" />
                <geometry>
                    <cylinder length="${height}" radius="${radius}" />
                </geometry>
            </collision>
            <inertial>
                <mass value="0.1" />
                <origin xyz="0 0 0" />
                <cylinder_inertia  m="0.1" r="${radius}" h="${height}" />
            </inertial>
        </link>

        <joint name="${name}_joint" type="prismatic">
            <parent link="${parent}"/>
            <child link="${name}"/>
            <origin xyz="${translateX} ${translateY} ${translateZ}" rpy="${rotationX} 0 0"/>
            <axis xyz="0 1 0"/>
            <limit effort="1000.0" lower="0" upper="0.2" velocity="0.5"/>
        </joint>

        <!-- gazebo extensions -->
        <xacro:bumper_gazebo name="${name}" collision="${collision}"/>
    </xacro:macro>
</robot>
